<?xml version="1.0"?>
<robot xmlns:xacro="http://www.ros.org/wiki/xacro" >
<xacro:include filename="inertial_macros.xacro" />

    <material name="white">
        <color rgba="1 1 1 1" />
    </material>

    <material name="orange">
        <color rgba="1 0.3 0.1 1"/>
    </material>

    <material name="blue">
        <color rgba="0.2 0.2 1 1"/>
    </material>

    <material name="black">
        <color rgba="0 0 0 1"/>
    </material>

    <material name="red">
        <color rgba="1 0 0 1"/>
    </material>



    <!-- BASE LINK  -->

    <link name="base_link">
    </link>

    <joint name="chassis_joint" type="fixed">
            <parent link="base_link"/>
            <child link="chassis"/>
            <origin xyz="0 0 0"/>
    </joint>



    <!-- CHASSIS OF ROBOT -->

    <link name="chassis">
        <visual>
            <origin xyz="0 0 0" rpy="0 0 0"/>
            <geometry>
                <mesh filename="file:///home/tony/drive_robot_ws/src/articubot_one/description/body/body_cammy.dae"/>
            </geometry>
            <material name="orange"/>
        </visual>
        <collision>
            <origin xyz="0 0 0.01" rpy="0 0 0"/>
            <geometry>
                <box size="0.3 0.3 0.05"/>
            </geometry>
        </collision>
            
        <xacro:inertial_box mass="100" x="0.3" y="0.3" z="0.04">
            <origin xyz="0 0 0.03" rpy="0 0 0"/>
        </xacro:inertial_box>
    </link>
    <gazebo reference="chassis">
        <material>Gazebo/Orange</material>
        <mu1 value="0.9"/>
        <mu2 value="0.9"/>
    </gazebo>


    <!-- BASE_FOOTPRINT LINK  -->

    <joint name="base_footprint_joint" type="fixed">
        <parent link="chassis"/>
        <child link="base_footprint"/>
        <origin xyz="0 0 0" rpy="0 0 0"/>
    </joint>

    <link name="base_footprint">
    </link>

    <!-- LEFT FRONT WHEEL -->

    <joint name="leftfront_wheel_joint" type="continuous">
        <parent link="chassis"/>
        <child link="leftfront_wheel"/>
        <origin xyz="0.115 0.18 0.03" rpy="0 0 0"/>
        <axis xyz="0 1 0"/>
        <dynamics damping="0.5" friction="0.9"/>
    </joint>
    <link name="leftfront_wheel">
        <visual>
            <origin xyz="0 0 0" rpy="0 0 0"/>
            <geometry>
                <mesh filename="file:///home/tony/drive_robot_ws/src/articubot_one/description/wheel/wheel.dae"/>
            </geometry>
            <material name="blue"/>
        </visual>
        <collision>
            <origin xyz="0 0 0" rpy="${pi/2} 0 0"/>
            <geometry>
                <cylinder length="0.05" radius="0.055" />
            </geometry>
        </collision>
        <xacro:inertial_cylinder mass="10" length="0.04" radius="0.04">
            <origin xyz="0 0 0" rpy="${pi/2} 0 0"/>
        </xacro:inertial_cylinder>
    </link>
    <gazebo reference="leftfront_wheel">
        <material>Gazebo/White</material>
        <mu1 value="0.9"/>
        <mu2 value="0.9"/>
    </gazebo>

    
    
    <!-- LEFT BACK WHEEL -->

    <joint name="leftback_wheel_joint" type="continuous">
        <parent link="chassis"/>
        <child link="leftback_wheel"/>
        <origin xyz="-0.115 0.18 0.03" rpy="0 0 0"/>
        <axis xyz="0 1 0"/>
        <dynamics damping="0.5" friction="0.9"/>
    </joint>
    <link name="leftback_wheel">
        <visual>
            <origin xyz="0 0 0" rpy="0 0 0"/>
            <geometry>
                <mesh filename="file:///home/tony/drive_robot_ws/src/articubot_one/description/wheel/wheel.dae"/>
            </geometry>
            <material name="blue"/>
        </visual>
        <collision>
            <origin xyz="0 0 0" rpy="${pi/2} 0 0"/>
            <geometry>
                <cylinder length="0.05" radius="0.055" />
            </geometry>
        </collision>
        <xacro:inertial_cylinder mass="10" length="0.04" radius="0.04">
            <origin xyz="0 0 0" rpy="${pi/2} 0 0"/>
        </xacro:inertial_cylinder>
    </link>
    <gazebo reference="leftback_wheel">
        <material>Gazebo/White</material>
        <mu1 value="0.9"/>
        <mu2 value="0.9"/>
    </gazebo>



    <!-- RIGHT FRONT WHEEL -->

    <joint name="rightfront_wheel_joint" type="continuous">
        <parent link="chassis"/>
        <child link="rightfront_wheel"/>
        <origin xyz="0.115 -0.18 0.03" rpy="0 0 0"/>
        <axis xyz="0 1 0"/>
        <dynamics damping="0.5" friction="0.9"/>
    </joint>
    <link name="rightfront_wheel">
        <visual>
            <origin xyz="0 0 0" rpy="0 0 0"/>
            <geometry>
                <mesh filename="file:///home/tony/drive_robot_ws/src/articubot_one/description/wheel/wheel.dae"/>
            </geometry>
            <material name="blue"/>
        </visual>
        <collision>
            <origin xyz="0 0 0" rpy="${pi/2} 0 0"/>
            <geometry>
                <cylinder length="0.05" radius="0.055" />
            </geometry>
        </collision>
        <xacro:inertial_cylinder mass="10" length="0.04" radius="0.04">
            <origin xyz="0 0 0" rpy="${pi/2} 0 0"/>
        </xacro:inertial_cylinder>
    </link>
    <gazebo reference="rightfront_wheel">
        <material>Gazebo/White</material>
        <mu1 value="0.9"/>
        <mu2 value="0.9"/>
    </gazebo>

    
    <!-- RIGHT BACK WHEEL -->

    <joint name="rightback_wheel_joint" type="continuous">
        <parent link="chassis"/>
        <child link="rightback_wheel"/>
        <origin xyz="-0.115 -0.18 0.03" rpy="0 0 0"/>
        <axis xyz="0 1 0"/>
        <dynamics damping="0.5" friction="0.9"/>
    </joint>
    <link name="rightback_wheel">
        <visual>
            <origin xyz="0 0 0" rpy="0 0 0"/>
            <geometry>
                <mesh filename="file:///home/tony/drive_robot_ws/src/articubot_one/description/wheel/wheel.dae"/>
            </geometry>
            <material name="blue"/>
        </visual>
        <collision>
            <origin xyz="0 0 0" rpy="${pi/2} 0 0"/>
            <geometry>
                <cylinder length="0.05" radius="0.055" />
            </geometry>
        </collision>
        <xacro:inertial_cylinder mass="10" length="0.04" radius="0.04">
            <origin xyz="0 0 0" rpy="${pi/2} 0 0"/>
        </xacro:inertial_cylinder>
    </link>
    <gazebo reference="rightback_wheel">
        <material>Gazebo/White</material>
        <mu1 value="0.9"/>
        <mu2 value="0.9"/>
    </gazebo>

    <!-- BASE ARM -->

    <joint name="base_arm_joint" type="revolute">
        <axis xyz="0 1 0"/>
        <limit effort="1000.0" lower="0.5" upper="1.25" velocity="0.5"/>
        <origin rpy="0 0 0" xyz="0 0.051 0.06"/>
        <parent link="chassis"/>
        <child link="base_arm"/>
        <dynamics damping="1" friction="1"/>
    </joint>
    <link name="base_arm">
        <visual>
            <origin xyz="0 0 0" rpy="0 0 0"/>
            <geometry>
                <mesh filename="file:///home/tony/drive_robot_ws/src/articubot_one/description/arm2/arm_2.dae"/>
            </geometry>
            <material name="blue"/>
        </visual>
        <collision>
            <origin xyz="0 0 0.12" rpy="0 0 0"/>
            <geometry>
                <cylinder length="0.25" radius="0.025" />
            </geometry>
        </collision>
        <xacro:inertial_cylinder mass="1" length="0.25" radius="0.025">
            <origin xyz="0 0 0.12" rpy="0 0 0"/>
        </xacro:inertial_cylinder>
    </link>
    <gazebo reference="base_arm">
        <material>Gazebo/White</material>
        <mu1 value="0.9"/>
        <mu2 value="0.9"/>
    </gazebo>

    <!-- MIDDLE ARM -->

    <joint name="mid_arm_joint" type="revolute">
        <axis xyz="0 1 0"/>
        <limit effort="1000.0" lower="-1.5" upper="-2.25" velocity="0.5"/>
        <origin rpy="0 0 0" xyz="0 -0.05 0.22"/>
        <parent link="base_arm"/>
        <child link="mid_arm"/>
        <dynamics damping="1" friction="1"/>
    </joint>
    <link name="mid_arm">
        <visual>
            <origin xyz="0 0 0" rpy="0 0 0"/>
            <geometry>
                <mesh filename="file:///home/tony/drive_robot_ws/src/articubot_one/description/arm_base/arm_base.dae"/>
            </geometry>
            <material name="blue"/>
        </visual>
        <collision>
            <origin xyz="0 0 0.12" rpy="0 0 0"/>
            <geometry>
                <cylinder length="0.25" radius="0.025" />
            </geometry>
        </collision>
        <xacro:inertial_cylinder mass="1" length="0.25" radius="0.025">
            <origin xyz="0 0 0.12" rpy="0 0 0"/>
        </xacro:inertial_cylinder>
    </link>
    <gazebo reference="mid_arm">
        <material>Gazebo/White</material>
        <mu1 value="0.1"/>
        <mu2 value="0.1"/>
    </gazebo>

    
</robot>